2019-04-25 13:31:46,752 ERROR: Exception on /login [GET] [in C:\ProgramData\Anaconda3\lib\site-packages\flask\app.py:1761]
Traceback (most recent call last):
  File "C:\ProgramData\Anaconda3\lib\site-packages\flask\app.py", line 2292, in wsgi_app
    response = self.full_dispatch_request()
  File "C:\ProgramData\Anaconda3\lib\site-packages\flask\app.py", line 1815, in full_dispatch_request
    rv = self.handle_user_exception(e)
  File "C:\ProgramData\Anaconda3\lib\site-packages\flask\app.py", line 1718, in handle_user_exception
    reraise(exc_type, exc_value, tb)
  File "C:\ProgramData\Anaconda3\lib\site-packages\flask\_compat.py", line 35, in reraise
    raise value
  File "C:\ProgramData\Anaconda3\lib\site-packages\flask\app.py", line 1813, in full_dispatch_request
    rv = self.dispatch_request()
  File "C:\ProgramData\Anaconda3\lib\site-packages\flask\app.py", line 1799, in dispatch_request
    return self.view_functions[rule.endpoint](**req.view_args)
  File "D:\PyCharm\Flask\app\routes.py", line 86, in login
    return render_template('login.html', title='Sign In', form=form)
  File "C:\ProgramData\Anaconda3\lib\site-packages\flask\templating.py", line 135, in render_template
    context, ctx.app)
  File "C:\ProgramData\Anaconda3\lib\site-packages\flask\templating.py", line 117, in _render
    rv = template.render(context)
  File "C:\ProgramData\Anaconda3\lib\site-packages\jinja2\asyncsupport.py", line 76, in render
    return original_render(self, *args, **kwargs)
  File "C:\ProgramData\Anaconda3\lib\site-packages\jinja2\environment.py", line 1008, in render
    return self.environment.handle_exception(exc_info, True)
  File "C:\ProgramData\Anaconda3\lib\site-packages\jinja2\environment.py", line 780, in handle_exception
    reraise(exc_type, exc_value, tb)
  File "C:\ProgramData\Anaconda3\lib\site-packages\jinja2\_compat.py", line 37, in reraise
    raise value.with_traceback(tb)
  File "D:\PyCharm\Flask\app\templates\login.html", line 2, in top-level template code
    {% import 'bootstrap/wtf.html' as wtf %}
  File "D:\PyCharm\Flask\app\templates\base.html", line 1, in top-level template code
    {% extends 'bootstrap/base.html' %}
  File "C:\ProgramData\Anaconda3\lib\site-packages\flask_bootstrap\templates\bootstrap\base.html", line 1, in top-level template code
    {% block doc -%}
  File "C:\ProgramData\Anaconda3\lib\site-packages\flask_bootstrap\templates\bootstrap\base.html", line 4, in block "doc"
    {%- block html %}
  File "C:\ProgramData\Anaconda3\lib\site-packages\flask_bootstrap\templates\bootstrap\base.html", line 20, in block "html"
    {% block body -%}
  File "C:\ProgramData\Anaconda3\lib\site-packages\flask_bootstrap\templates\bootstrap\base.html", line 21, in block "body"
    {% block navbar %}
  File "D:\PyCharm\Flask\app\templates\base.html", line 23, in block "navbar"
    <li><a href="{{ url_for('dvore') }}">{{ _('Двор') }}</a></li>
  File "C:\ProgramData\Anaconda3\lib\site-packages\flask\helpers.py", line 356, in url_for
    return appctx.app.handle_url_build_error(error, endpoint, values)
  File "C:\ProgramData\Anaconda3\lib\site-packages\flask\app.py", line 2061, in handle_url_build_error
    reraise(exc_type, exc_value, tb)
  File "C:\ProgramData\Anaconda3\lib\site-packages\flask\_compat.py", line 35, in reraise
    raise value
  File "C:\ProgramData\Anaconda3\lib\site-packages\flask\helpers.py", line 345, in url_for
    force_external=external)
  File "C:\ProgramData\Anaconda3\lib\site-packages\werkzeug\routing.py", line 1776, in build
    raise BuildError(endpoint, values, method, self)
werkzeug.routing.BuildError: Could not build url for endpoint 'dvore'. Did you mean 'dvor' instead?
2019-04-25 13:32:41,648 INFO: Microblog startup [in D:\PyCharm\Flask\app\errors.py:45]
2019-04-25 13:40:23,799 INFO: Microblog startup [in D:\PyCharm\Flask\app\errors.py:45]
2019-04-25 13:40:37,042 INFO: Microblog startup [in D:\PyCharm\Flask\app\errors.py:45]
2019-04-25 13:41:00,939 INFO: Microblog startup [in D:\PyCharm\Flask\app\errors.py:45]
2019-04-25 13:54:35,458 INFO: Microblog startup [in D:\PyCharm\Flask\app\errors.py:45]
2019-04-25 13:54:38,438 ERROR: Exception on /index [GET] [in C:\ProgramData\Anaconda3\lib\site-packages\flask\app.py:1761]
Traceback (most recent call last):
  File "C:\ProgramData\Anaconda3\lib\site-packages\sqlalchemy\orm\base.py", line 379, in _entity_descriptor
    return getattr(entity, key)
AttributeError: type object 'Post' has no attribute 'opros'

During handling of the above exception, another exception occurred:

Traceback (most recent call last):
  File "C:\ProgramData\Anaconda3\lib\site-packages\flask\app.py", line 2292, in wsgi_app
    response = self.full_dispatch_request()
  File "C:\ProgramData\Anaconda3\lib\site-packages\flask\app.py", line 1815, in full_dispatch_request
    rv = self.handle_user_exception(e)
  File "C:\ProgramData\Anaconda3\lib\site-packages\flask\app.py", line 1718, in handle_user_exception
    reraise(exc_type, exc_value, tb)
  File "C:\ProgramData\Anaconda3\lib\site-packages\flask\_compat.py", line 35, in reraise
    raise value
  File "C:\ProgramData\Anaconda3\lib\site-packages\flask\app.py", line 1813, in full_dispatch_request
    rv = self.dispatch_request()
  File "C:\ProgramData\Anaconda3\lib\site-packages\flask\app.py", line 1799, in dispatch_request
    return self.view_functions[rule.endpoint](**req.view_args)
  File "C:\ProgramData\Anaconda3\lib\site-packages\flask_login\utils.py", line 261, in decorated_view
    return func(*args, **kwargs)
  File "D:\PyCharm\Flask\app\routes.py", line 48, in index
    posts = current_user.followed_posts().filter_by(opros=0).paginate(
  File "C:\ProgramData\Anaconda3\lib\site-packages\sqlalchemy\orm\query.py", line 1632, in filter_by
    for key, value in kwargs.items()]
  File "C:\ProgramData\Anaconda3\lib\site-packages\sqlalchemy\orm\query.py", line 1632, in <listcomp>
    for key, value in kwargs.items()]
  File "C:\ProgramData\Anaconda3\lib\site-packages\sqlalchemy\orm\base.py", line 383, in _entity_descriptor
    (description, key)
sqlalchemy.exc.InvalidRequestError: Entity '<class 'app.models.Post'>' has no property 'opros'
2019-04-25 13:55:34,510 INFO: Microblog startup [in D:\PyCharm\Flask\app\errors.py:45]
