2019-04-25 13:57:15,406 ERROR: Exception on /index [GET] [in C:\ProgramData\Anaconda3\lib\site-packages\flask\app.py:1761]
Traceback (most recent call last):
  File "C:\ProgramData\Anaconda3\lib\site-packages\flask\app.py", line 2292, in wsgi_app
    response = self.full_dispatch_request()
  File "C:\ProgramData\Anaconda3\lib\site-packages\flask\app.py", line 1815, in full_dispatch_request
    rv = self.handle_user_exception(e)
  File "C:\ProgramData\Anaconda3\lib\site-packages\flask\app.py", line 1718, in handle_user_exception
    reraise(exc_type, exc_value, tb)
  File "C:\ProgramData\Anaconda3\lib\site-packages\flask\_compat.py", line 35, in reraise
    raise value
  File "C:\ProgramData\Anaconda3\lib\site-packages\flask\app.py", line 1813, in full_dispatch_request
    rv = self.dispatch_request()
  File "C:\ProgramData\Anaconda3\lib\site-packages\flask\app.py", line 1799, in dispatch_request
    return self.view_functions[rule.endpoint](**req.view_args)
  File "C:\ProgramData\Anaconda3\lib\site-packages\flask_login\utils.py", line 261, in decorated_view
    return func(*args, **kwargs)
  File "D:\PyCharm\Flask\app\routes.py", line 56, in index
    prev_url=prev_url, opros=False)
  File "C:\ProgramData\Anaconda3\lib\site-packages\flask\templating.py", line 135, in render_template
    context, ctx.app)
  File "C:\ProgramData\Anaconda3\lib\site-packages\flask\templating.py", line 117, in _render
    rv = template.render(context)
  File "C:\ProgramData\Anaconda3\lib\site-packages\jinja2\asyncsupport.py", line 76, in render
    return original_render(self, *args, **kwargs)
  File "C:\ProgramData\Anaconda3\lib\site-packages\jinja2\environment.py", line 1008, in render
    return self.environment.handle_exception(exc_info, True)
  File "C:\ProgramData\Anaconda3\lib\site-packages\jinja2\environment.py", line 780, in handle_exception
    reraise(exc_type, exc_value, tb)
  File "C:\ProgramData\Anaconda3\lib\site-packages\jinja2\_compat.py", line 37, in reraise
    raise value.with_traceback(tb)
  File "D:\PyCharm\Flask\app\templates\index.html", line 2, in top-level template code
    {% import 'bootstrap/wtf.html' as wtf %}
  File "D:\PyCharm\Flask\app\templates\base.html", line 1, in top-level template code
    {% extends 'bootstrap/base.html' %}
  File "C:\ProgramData\Anaconda3\lib\site-packages\flask_bootstrap\templates\bootstrap\base.html", line 1, in top-level template code
    {% block doc -%}
  File "C:\ProgramData\Anaconda3\lib\site-packages\flask_bootstrap\templates\bootstrap\base.html", line 4, in block "doc"
    {%- block html %}
  File "C:\ProgramData\Anaconda3\lib\site-packages\flask_bootstrap\templates\bootstrap\base.html", line 20, in block "html"
    {% block body -%}
  File "C:\ProgramData\Anaconda3\lib\site-packages\flask_bootstrap\templates\bootstrap\base.html", line 23, in block "body"
    {% block content -%}
  File "D:\PyCharm\Flask\app\templates\base.html", line 49, in block "content"
    {% block app_content %}{% endblock %}
  File "D:\PyCharm\Flask\app\templates\index.html", line 11, in block "app_content"
    {% include 'postWithOpros.html' %}
  File "D:\PyCharm\Flask\app\templates\postWithOpros.html", line 16, in top-level template code
    <p><a href="{{ url_for('pod—', numb=post.id) }}">œÓ‰‰ÂÊË‚‡˛</a> {{ post.pod }}</p>
  File "C:\ProgramData\Anaconda3\lib\site-packages\flask\helpers.py", line 356, in url_for
    return appctx.app.handle_url_build_error(error, endpoint, values)
  File "C:\ProgramData\Anaconda3\lib\site-packages\flask\app.py", line 2061, in handle_url_build_error
    reraise(exc_type, exc_value, tb)
  File "C:\ProgramData\Anaconda3\lib\site-packages\flask\_compat.py", line 35, in reraise
    raise value
  File "C:\ProgramData\Anaconda3\lib\site-packages\flask\helpers.py", line 345, in url_for
    force_external=external)
  File "C:\ProgramData\Anaconda3\lib\site-packages\werkzeug\routing.py", line 1776, in build
    raise BuildError(endpoint, values, method, self)
werkzeug.routing.BuildError: Could not build url for endpoint 'pod—' with values ['numb']. Did you mean 'podC' instead?
2019-04-25 13:57:49,842 INFO: Microblog startup [in D:\PyCharm\Flask\app\errors.py:45]
2019-04-25 14:03:38,398 INFO: Microblog startup [in D:\PyCharm\Flask\app\errors.py:45]
2019-04-25 14:03:48,179 INFO: Microblog startup [in D:\PyCharm\Flask\app\errors.py:45]
2019-04-25 14:03:59,631 INFO: Microblog startup [in D:\PyCharm\Flask\app\errors.py:45]
2019-04-25 14:18:16,152 INFO: Microblog startup [in D:\PyCharm\Flask\app\errors.py:45]
2019-04-25 14:18:18,630 ERROR: Exception on /index [GET] [in C:\ProgramData\Anaconda3\lib\site-packages\flask\app.py:1761]
Traceback (most recent call last):
  File "C:\ProgramData\Anaconda3\lib\site-packages\sqlalchemy\ext\declarative\clsregistry.py", line 281, in __call__
    x = eval(self.arg, globals(), self._dict)
  File "<string>", line 1, in <module>
NameError: name 'Feedback' is not defined

During handling of the above exception, another exception occurred:

Traceback (most recent call last):
  File "C:\ProgramData\Anaconda3\lib\site-packages\flask\app.py", line 2292, in wsgi_app
    response = self.full_dispatch_request()
  File "C:\ProgramData\Anaconda3\lib\site-packages\flask\app.py", line 1815, in full_dispatch_request
    rv = self.handle_user_exception(e)
  File "C:\ProgramData\Anaconda3\lib\site-packages\flask\app.py", line 1718, in handle_user_exception
    reraise(exc_type, exc_value, tb)
  File "C:\ProgramData\Anaconda3\lib\site-packages\flask\_compat.py", line 35, in reraise
    raise value
  File "C:\ProgramData\Anaconda3\lib\site-packages\flask\app.py", line 1811, in full_dispatch_request
    rv = self.preprocess_request()
  File "C:\ProgramData\Anaconda3\lib\site-packages\flask\app.py", line 2087, in preprocess_request
    rv = func()
  File "D:\PyCharm\Flask\app\routes.py", line 26, in before_request
    if current_user.is_authenticated:
  File "C:\ProgramData\Anaconda3\lib\site-packages\werkzeug\local.py", line 347, in __getattr__
    return getattr(self._get_current_object(), name)
  File "C:\ProgramData\Anaconda3\lib\site-packages\werkzeug\local.py", line 306, in _get_current_object
    return self.__local()
  File "C:\ProgramData\Anaconda3\lib\site-packages\flask_login\utils.py", line 26, in <lambda>
    current_user = LocalProxy(lambda: _get_user())
  File "C:\ProgramData\Anaconda3\lib\site-packages\flask_login\utils.py", line 335, in _get_user
    current_app.login_manager._load_user()
  File "C:\ProgramData\Anaconda3\lib\site-packages\flask_login\login_manager.py", line 359, in _load_user
    return self.reload_user()
  File "C:\ProgramData\Anaconda3\lib\site-packages\flask_login\login_manager.py", line 321, in reload_user
    user = self.user_callback(user_id)
  File "D:\PyCharm\Flask\app\models.py", line 20, in load_user
    return User.query.get(int(id))
  File "C:\ProgramData\Anaconda3\lib\site-packages\flask_sqlalchemy\__init__.py", line 512, in __get__
    mapper = orm.class_mapper(type)
  File "C:\ProgramData\Anaconda3\lib\site-packages\sqlalchemy\orm\base.py", line 421, in class_mapper
    mapper = _inspect_mapped_class(class_, configure=configure)
  File "C:\ProgramData\Anaconda3\lib\site-packages\sqlalchemy\orm\base.py", line 400, in _inspect_mapped_class
    mapper._configure_all()
  File "C:\ProgramData\Anaconda3\lib\site-packages\sqlalchemy\orm\mapper.py", line 1272, in _configure_all
    configure_mappers()
  File "C:\ProgramData\Anaconda3\lib\site-packages\sqlalchemy\orm\mapper.py", line 3029, in configure_mappers
    mapper._post_configure_properties()
  File "C:\ProgramData\Anaconda3\lib\site-packages\sqlalchemy\orm\mapper.py", line 1828, in _post_configure_properties
    prop.init()
  File "C:\ProgramData\Anaconda3\lib\site-packages\sqlalchemy\orm\interfaces.py", line 184, in init
    self.do_init()
  File "C:\ProgramData\Anaconda3\lib\site-packages\sqlalchemy\orm\relationships.py", line 1655, in do_init
    self._process_dependent_arguments()
  File "C:\ProgramData\Anaconda3\lib\site-packages\sqlalchemy\orm\relationships.py", line 1712, in _process_dependent_arguments
    self.target = self.mapper.mapped_table
  File "C:\ProgramData\Anaconda3\lib\site-packages\sqlalchemy\util\langhelpers.py", line 767, in __get__
    obj.__dict__[self.__name__] = result = self.fget(obj)
  File "C:\ProgramData\Anaconda3\lib\site-packages\sqlalchemy\orm\relationships.py", line 1628, in mapper
    argument = self.argument()
  File "C:\ProgramData\Anaconda3\lib\site-packages\sqlalchemy\ext\declarative\clsregistry.py", line 293, in __call__
    (self.prop.parent, self.arg, n.args[0], self.cls)
sqlalchemy.exc.InvalidRequestError: When initializing mapper Mapper|User|user, expression 'Feedback' failed to locate a name ("name 'Feedback' is not defined"). If this is a class name, consider adding this relationship() to the <class 'app.models.User'> class after both dependent classes have been defined.
2019-04-25 14:20:03,646 INFO: Microblog startup [in D:\PyCharm\Flask\app\errors.py:45]
2019-04-25 14:20:18,593 INFO: Microblog startup [in D:\PyCharm\Flask\app\errors.py:45]
2019-04-25 14:20:41,036 INFO: Microblog startup [in D:\PyCharm\Flask\app\errors.py:45]
2019-04-25 14:20:51,710 INFO: Microblog startup [in D:\PyCharm\Flask\app\errors.py:45]
2019-04-25 14:22:04,429 INFO: Microblog startup [in D:\PyCharm\Flask\app\errors.py:45]
2019-04-25 14:22:19,188 INFO: Microblog startup [in D:\PyCharm\Flask\app\errors.py:45]
